{"uuid": "39a41fde-6618-4892-bb18-17b0e69301f1", "children": ["d120005b-3e14-46ba-b254-1069ed0af912"], "befores": [{"name": "web_driver", "status": "broken", "statusDetails": {"message": "urllib3.exceptions.MaxRetryError: HTTPConnectionPool(host='172.26.21.92', port=4444): Max retries exceeded with url: /wd/hub/session (Caused by NewConnectionError('<urllib3.connection.HTTPConnection object at 0x055E9750>: Failed to establish a new connection: [WinError 10061] No connection could be made because the target machine actively refused it'))\n", "trace": "  File \"D:\\Workspace\\pyenv\\lib\\site-packages\\pluggy-0.9.0-py3.7.egg\\pluggy\\callers.py\", line 187, in _multicall\n    res = hook_impl.function(*args)\n  File \"D:\\Workspace\\pyenv\\lib\\site-packages\\pytest-4.4.0-py3.7.egg\\_pytest\\fixtures.py\", line 935, in pytest_fixture_setup\n    result = call_fixture_func(fixturefunc, request, kwargs)\n  File \"D:\\Workspace\\pyenv\\lib\\site-packages\\pytest-4.4.0-py3.7.egg\\_pytest\\fixtures.py\", line 790, in call_fixture_func\n    res = next(it)\n  File \"D:\\Workspace\\pyautomation\\pyautomation\\web\\webtest.py\", line 21, in web_driver\n    self.driver = WebDrivers().get()\n  File \"D:\\Workspace\\pyautomation\\pyautomation\\drivers\\web_drivers.py\", line 85, in get\n    return WebDrivers.__getattribute__(WebDrivers(), browser)\n  File \"D:\\Workspace\\pyautomation\\pyautomation\\drivers\\web_drivers.py\", line 65, in firefox\n    options=options)\n  File \"D:\\Workspace\\pyenv\\lib\\site-packages\\selenium\\webdriver\\remote\\webdriver.py\", line 157, in __init__\n    self.start_session(capabilities, browser_profile)\n  File \"D:\\Workspace\\pyenv\\lib\\site-packages\\selenium\\webdriver\\remote\\webdriver.py\", line 252, in start_session\n    response = self.execute(Command.NEW_SESSION, parameters)\n  File \"D:\\Workspace\\pyenv\\lib\\site-packages\\selenium\\webdriver\\remote\\webdriver.py\", line 319, in execute\n    response = self.command_executor.execute(driver_command, params)\n  File \"D:\\Workspace\\pyenv\\lib\\site-packages\\selenium\\webdriver\\remote\\remote_connection.py\", line 374, in execute\n    return self._request(command_info[0], url, body=data)\n  File \"D:\\Workspace\\pyenv\\lib\\site-packages\\selenium\\webdriver\\remote\\remote_connection.py\", line 402, in _request\n    resp = http.request(method, url, body=body, headers=headers)\n  File \"D:\\Workspace\\pyenv\\lib\\site-packages\\urllib3-1.24.1-py3.7.egg\\urllib3\\request.py\", line 72, in request\n    **urlopen_kw)\n  File \"D:\\Workspace\\pyenv\\lib\\site-packages\\urllib3-1.24.1-py3.7.egg\\urllib3\\request.py\", line 150, in request_encode_body\n    return self.urlopen(method, url, **extra_kw)\n  File \"D:\\Workspace\\pyenv\\lib\\site-packages\\urllib3-1.24.1-py3.7.egg\\urllib3\\poolmanager.py\", line 323, in urlopen\n    response = conn.urlopen(method, u.request_uri, **kw)\n  File \"D:\\Workspace\\pyenv\\lib\\site-packages\\urllib3-1.24.1-py3.7.egg\\urllib3\\connectionpool.py\", line 667, in urlopen\n    **response_kw)\n  File \"D:\\Workspace\\pyenv\\lib\\site-packages\\urllib3-1.24.1-py3.7.egg\\urllib3\\connectionpool.py\", line 667, in urlopen\n    **response_kw)\n  File \"D:\\Workspace\\pyenv\\lib\\site-packages\\urllib3-1.24.1-py3.7.egg\\urllib3\\connectionpool.py\", line 667, in urlopen\n    **response_kw)\n  File \"D:\\Workspace\\pyenv\\lib\\site-packages\\urllib3-1.24.1-py3.7.egg\\urllib3\\connectionpool.py\", line 638, in urlopen\n    _stacktrace=sys.exc_info()[2])\n  File \"D:\\Workspace\\pyenv\\lib\\site-packages\\urllib3-1.24.1-py3.7.egg\\urllib3\\util\\retry.py\", line 398, in increment\n    raise MaxRetryError(_pool, url, error or ResponseError(cause))\n"}, "start": 1557218200412, "stop": 1557218205437}], "start": 1557218200412, "stop": 1557218205661}